

[STDERR]
Traceback (most recent call last):
  File "C:\Users\SAHINO\AppData\Roaming\Python\Python313\site-packages\pymysql\connections.py", line 661, in connect
    sock = socket.create_connection(
        (self.host, self.port), self.connect_timeout, **kwargs
    )
  File "C:\Program Files\Python313\Lib\socket.py", line 864, in create_connection
    raise exceptions[0]
  File "C:\Program Files\Python313\Lib\socket.py", line 849, in create_connection
    sock.connect(sa)
    ~~~~~~~~~~~~^^^^
ConnectionRefusedError: [WinError 10061] Aucune connexion n’a pu être établie car l’ordinateur cible l’a expressément refusée

During handling of the above exception, another exception occurred:

Traceback (most recent call last):
  File "C:\Users\SAHINO\AppData\Roaming\Python\Python313\site-packages\sqlalchemy\engine\base.py", line 143, in __init__
    self._dbapi_connection = engine.raw_connection()
                             ~~~~~~~~~~~~~~~~~~~~~^^
  File "C:\Users\SAHINO\AppData\Roaming\Python\Python313\site-packages\sqlalchemy\engine\base.py", line 3301, in raw_connection
    return self.pool.connect()
           ~~~~~~~~~~~~~~~~~^^
  File "C:\Users\SAHINO\AppData\Roaming\Python\Python313\site-packages\sqlalchemy\pool\base.py", line 447, in connect
    return _ConnectionFairy._checkout(self)
           ~~~~~~~~~~~~~~~~~~~~~~~~~~^^^^^^
  File "C:\Users\SAHINO\AppData\Roaming\Python\Python313\site-packages\sqlalchemy\pool\base.py", line 1264, in _checkout
    fairy = _ConnectionRecord.checkout(pool)
  File "C:\Users\SAHINO\AppData\Roaming\Python\Python313\site-packages\sqlalchemy\pool\base.py", line 711, in checkout
    rec = pool._do_get()
  File "C:\Users\SAHINO\AppData\Roaming\Python\Python313\site-packages\sqlalchemy\pool\impl.py", line 177, in _do_get
    with util.safe_reraise():
         ~~~~~~~~~~~~~~~~~^^
  File "C:\Users\SAHINO\AppData\Roaming\Python\Python313\site-packages\sqlalchemy\util\langhelpers.py", line 224, in __exit__
    raise exc_value.with_traceback(exc_tb)
  File "C:\Users\SAHINO\AppData\Roaming\Python\Python313\site-packages\sqlalchemy\pool\impl.py", line 175, in _do_get
    return self._create_connection()
           ~~~~~~~~~~~~~~~~~~~~~~~^^
  File "C:\Users\SAHINO\AppData\Roaming\Python\Python313\site-packages\sqlalchemy\pool\base.py", line 388, in _create_connection
    return _ConnectionRecord(self)
  File "C:\Users\SAHINO\AppData\Roaming\Python\Python313\site-packages\sqlalchemy\pool\base.py", line 673, in __init__
    self.__connect()
    ~~~~~~~~~~~~~~^^
  File "C:\Users\SAHINO\AppData\Roaming\Python\Python313\site-packages\sqlalchemy\pool\base.py", line 899, in __connect
    with util.safe_reraise():
         ~~~~~~~~~~~~~~~~~^^
  File "C:\Users\SAHINO\AppData\Roaming\Python\Python313\site-packages\sqlalchemy\util\langhelpers.py", line 224, in __exit__
    raise exc_value.with_traceback(exc_tb)
  File "C:\Users\SAHINO\AppData\Roaming\Python\Python313\site-packages\sqlalchemy\pool\base.py", line 895, in __connect
    self.dbapi_connection = connection = pool._invoke_creator(self)
                                         ~~~~~~~~~~~~~~~~~~~~^^^^^^
  File "C:\Users\SAHINO\AppData\Roaming\Python\Python313\site-packages\sqlalchemy\engine\create.py", line 661, in connect
    return dialect.connect(*cargs, **cparams)
           ~~~~~~~~~~~~~~~^^^^^^^^^^^^^^^^^^^
  File "C:\Users\SAHINO\AppData\Roaming\Python\Python313\site-packages\sqlalchemy\engine\default.py", line 629, in connect
    return self.loaded_dbapi.connect(*cargs, **cparams)  # type: ignore[no-any-return]  # NOQA: E501
           ~~~~~~~~~~~~~~~~~~~~~~~~~^^^^^^^^^^^^^^^^^^^
  File "C:\Users\SAHINO\AppData\Roaming\Python\Python313\site-packages\pymysql\connections.py", line 365, in __init__
    self.connect()
    ~~~~~~~~~~~~^^
  File "C:\Users\SAHINO\AppData\Roaming\Python\Python313\site-packages\pymysql\connections.py", line 723, in connect
    raise exc
pymysql.err.OperationalError: (2003, "Can't connect to MySQL server on '127.0.0.1' ([WinError 10061] Aucune connexion n’a pu être établie car l’ordinateur cible l’a expressément refusée)")

The above exception was the direct cause of the following exception:

Traceback (most recent call last):
  File "C:\Users\SAHINO\Desktop\test\fraudes_DICT\flask_fraude_app\fraude_detect_admi.py", line 53, in <module>
    with engine.begin() as conn:
         ~~~~~~~~~~~~^^
  File "C:\Program Files\Python313\Lib\contextlib.py", line 141, in __enter__
    return next(self.gen)
  File "C:\Users\SAHINO\AppData\Roaming\Python\Python313\site-packages\sqlalchemy\engine\base.py", line 3241, in begin
    with self.connect() as conn:
         ~~~~~~~~~~~~^^
  File "C:\Users\SAHINO\AppData\Roaming\Python\Python313\site-packages\sqlalchemy\engine\base.py", line 3277, in connect
    return self._connection_cls(self)
           ~~~~~~~~~~~~~~~~~~~~^^^^^^
  File "C:\Users\SAHINO\AppData\Roaming\Python\Python313\site-packages\sqlalchemy\engine\base.py", line 145, in __init__
    Connection._handle_dbapi_exception_noconnection(
    ~~~~~~~~~~~~~~~~~~~~~~~~~~~~~~~~~~~~~~~~~~~~~~~^
        err, dialect, engine
        ^^^^^^^^^^^^^^^^^^^^
    )
    ^
  File "C:\Users\SAHINO\AppData\Roaming\Python\Python313\site-packages\sqlalchemy\engine\base.py", line 2440, in _handle_dbapi_exception_noconnection
    raise sqlalchemy_exception.with_traceback(exc_info[2]) from e
  File "C:\Users\SAHINO\AppData\Roaming\Python\Python313\site-packages\sqlalchemy\engine\base.py", line 143, in __init__
    self._dbapi_connection = engine.raw_connection()
                             ~~~~~~~~~~~~~~~~~~~~~^^
  File "C:\Users\SAHINO\AppData\Roaming\Python\Python313\site-packages\sqlalchemy\engine\base.py", line 3301, in raw_connection
    return self.pool.connect()
           ~~~~~~~~~~~~~~~~~^^
  File "C:\Users\SAHINO\AppData\Roaming\Python\Python313\site-packages\sqlalchemy\pool\base.py", line 447, in connect
    return _ConnectionFairy._checkout(self)
           ~~~~~~~~~~~~~~~~~~~~~~~~~~^^^^^^
  File "C:\Users\SAHINO\AppData\Roaming\Python\Python313\site-packages\sqlalchemy\pool\base.py", line 1264, in _checkout
    fairy = _ConnectionRecord.checkout(pool)
  File "C:\Users\SAHINO\AppData\Roaming\Python\Python313\site-packages\sqlalchemy\pool\base.py", line 711, in checkout
    rec = pool._do_get()
  File "C:\Users\SAHINO\AppData\Roaming\Python\Python313\site-packages\sqlalchemy\pool\impl.py", line 177, in _do_get
    with util.safe_reraise():
         ~~~~~~~~~~~~~~~~~^^
  File "C:\Users\SAHINO\AppData\Roaming\Python\Python313\site-packages\sqlalchemy\util\langhelpers.py", line 224, in __exit__
    raise exc_value.with_traceback(exc_tb)
  File "C:\Users\SAHINO\AppData\Roaming\Python\Python313\site-packages\sqlalchemy\pool\impl.py", line 175, in _do_get
    return self._create_connection()
           ~~~~~~~~~~~~~~~~~~~~~~~^^
  File "C:\Users\SAHINO\AppData\Roaming\Python\Python313\site-packages\sqlalchemy\pool\base.py", line 388, in _create_connection
    return _ConnectionRecord(self)
  File "C:\Users\SAHINO\AppData\Roaming\Python\Python313\site-packages\sqlalchemy\pool\base.py", line 673, in __init__
    self.__connect()
    ~~~~~~~~~~~~~~^^
  File "C:\Users\SAHINO\AppData\Roaming\Python\Python313\site-packages\sqlalchemy\pool\base.py", line 899, in __connect
    with util.safe_reraise():
         ~~~~~~~~~~~~~~~~~^^
  File "C:\Users\SAHINO\AppData\Roaming\Python\Python313\site-packages\sqlalchemy\util\langhelpers.py", line 224, in __exit__
    raise exc_value.with_traceback(exc_tb)
  File "C:\Users\SAHINO\AppData\Roaming\Python\Python313\site-packages\sqlalchemy\pool\base.py", line 895, in __connect
    self.dbapi_connection = connection = pool._invoke_creator(self)
                                         ~~~~~~~~~~~~~~~~~~~~^^^^^^
  File "C:\Users\SAHINO\AppData\Roaming\Python\Python313\site-packages\sqlalchemy\engine\create.py", line 661, in connect
    return dialect.connect(*cargs, **cparams)
           ~~~~~~~~~~~~~~~^^^^^^^^^^^^^^^^^^^
  File "C:\Users\SAHINO\AppData\Roaming\Python\Python313\site-packages\sqlalchemy\engine\default.py", line 629, in connect
    return self.loaded_dbapi.connect(*cargs, **cparams)  # type: ignore[no-any-return]  # NOQA: E501
           ~~~~~~~~~~~~~~~~~~~~~~~~~^^^^^^^^^^^^^^^^^^^
  File "C:\Users\SAHINO\AppData\Roaming\Python\Python313\site-packages\pymysql\connections.py", line 365, in __init__
    self.connect()
    ~~~~~~~~~~~~^^
  File "C:\Users\SAHINO\AppData\Roaming\Python\Python313\site-packages\pymysql\connections.py", line 723, in connect
    raise exc
sqlalchemy.exc.OperationalError: (pymysql.err.OperationalError) (2003, "Can't connect to MySQL server on '127.0.0.1' ([WinError 10061] Aucune connexion n’a pu être établie car l’ordinateur cible l’a expressément refusée)")
(Background on this error at: https://sqlalche.me/e/20/e3q8)
